<robot
  name="disturbance_generator">
  <link
    name="base_link">
    <inertial>
      <origin
        xyz="0 0 0.027"
        rpy="0 0 0" />
      <mass
        value="1" />
      <inertia
        ixx="0.001"
        ixy="0"
        ixz="0"
        iyy="0"
        iyz="0"
        izz="0.001" />
    </inertial>
    <visual>
      <origin
        xyz="0 0 0"
        rpy="0 0 0" />
      <geometry>
        <mesh
          filename="package://disturbance_generator/meshes/base_link.STL" />
      </geometry>
      <material
        name="">
        <color
          rgba="0.79216 0.81961 0.93333 1" />
      </material>
    </visual>
    <collision>
      <origin
        xyz="0 0 0"
        rpy="0 0 0" />
      <geometry>
        <mesh
          filename="package://disturbance_generator/meshes/base_link.STL" />
      </geometry>
    </collision>
  </link>
  <link
    name="rod_link">
    <inertial>
      <origin
        xyz="0 0 -0.507"
        rpy="0 0 0" />
      <mass
        value="1" />
      <inertia
        ixx="0.097"
        ixy="0"
        ixz="0"
        iyy="0.097"
        iyz="0"
        izz="0" />
    </inertial>
    <visual>
      <origin
        xyz="0 0 0"
        rpy="0 0 0" />
      <geometry>
        <mesh
          filename="package://disturbance_generator/meshes/rod_link.STL" />
      </geometry>
      <material
        name="">
        <color
          rgba="0.79216 0.81961 0.93333 1" />
      </material>
    </visual>
    <collision>
      <origin
        xyz="0 0 0"
        rpy="0 0 0" />
      <geometry>
        <mesh
          filename="package://disturbance_generator/meshes/rod_link.STL" />
      </geometry>
    </collision>
  </link>
  <joint
    name="rod_joint"
    type="continuous">
    <origin
      xyz="0 0 0"
      rpy="0 0 0" />
    <parent
      link="base_link" />
    <child
      link="rod_link" />
    <axis
      xyz="1 0 0" />
  </joint>
  <link
    name="mass_link">
    <inertial>
      <origin
        xyz="0 0 -0.29"
        rpy="0 0 0" />
      <mass
        value="15" />
      <inertia
        ixx="0.625"
        ixy="0"
        ixz="0"
        iyy="1.562"
        iyz="0"
        izz="1.562" />
    </inertial>
    <visual>
      <origin
        xyz="0 0 0"
        rpy="0 0 0" />
      <geometry>
        <mesh
          filename="package://disturbance_generator/meshes/mass_link.STL" />
      </geometry>
      <material
        name="">
        <color
          rgba="0.79216 0.81961 0.93333 1" />
      </material>
    </visual>
    <collision>
      <origin
        xyz="0 0 0"
        rpy="0 0 0" />
      <geometry>
        <mesh
          filename="package://disturbance_generator/meshes/mass_link.STL" />
      </geometry>
    </collision>
  </link>
  <joint
    name="mass_joint"
    type="continuous">
    <origin
      xyz="0 0 -1.015"
      rpy="0 0 0" />
    <parent
      link="rod_link" />
    <child
      link="mass_link" />
    <axis
      xyz="1 0 0" />
  </joint>
</robot>