<sdf version='1.6'>
  <model name='disturbance_generator'>

  <joint name="fixed to ground" type="fixed">
    <parent>world</parent>
    <child>base_link</child>
  </joint>

    <link name='base_link'>
      <pose frame=''>0 0 0 0 -0 0</pose>
      <inertial>
        <pose frame=''>0 0 0.027 0 -0 0</pose>
        <mass>1</mass>
        <inertia>
          <ixx>0.001</ixx>
          <ixy>0</ixy>
          <ixz>0</ixz>
          <iyy>0</iyy>
          <iyz>0</iyz>
          <izz>0.001</izz>
        </inertia>
      </inertial>
      <!-- <collision name='base_link_collision'>
        <pose frame=''>0 0 0 0 -0 0</pose>
        <geometry>
          <mesh>
            <scale>1 1 1</scale>
            <uri>model://disturbance_generator/meshes/base_link.STL</uri>
          </mesh>
        </geometry>
      </collision> -->
      <visual name='base_link_visual'>
        <pose frame=''>0 0 0 0 -0 0</pose>
        <geometry>
          <mesh>
            <scale>1 1 1</scale>
            <uri>model://disturbance_generator/meshes/base_link.STL</uri>
          </mesh>
        </geometry>
      </visual>
    </link>
    <link name='rod_link'>
      <pose frame=''>0 0 0 0 -0 0</pose>
      <inertial>
        <pose frame=''>0 0 -0.507 0 -0 0</pose>
        <mass>1</mass>
        <inertia>
          <ixx>0.097</ixx>
          <ixy>0</ixy>
          <ixz>0</ixz>
          <iyy>0.097</iyy>
          <iyz>0</iyz>
          <izz>0</izz>
        </inertia>
      </inertial>
      <!-- <collision name='rod_link_collision'>
        <pose frame=''>0 0 0 0 -0 0</pose>
        <geometry>
          <mesh>
            <scale>1 1 1</scale>
            <uri>model://disturbance_generator/meshes/rod_link.STL</uri>
          </mesh>
        </geometry>
      </collision> -->
      <visual name='rod_link_visual'>
        <pose frame=''>0 0 0 0 -0 0</pose>
        <geometry>
          <mesh>
            <scale>1 1 1</scale>
            <uri>model://disturbance_generator/meshes/rod_link.STL</uri>
          </mesh>
        </geometry>
      </visual>
    </link>
    <joint name='rod_joint' type='revolute'>
      <child>rod_link</child>
      <parent>base_link</parent>
      <axis>
        <xyz>1 0 0</xyz>
        <limit>
          <lower>-1.5707</lower>
          <upper>1.5707</upper>
        </limit>
        <dynamics>
          <spring_reference>0</spring_reference>
          <spring_stiffness>0</spring_stiffness>
        </dynamics>
        <use_parent_model_frame>1</use_parent_model_frame>
      </axis>
    </joint>
    <link name='mass_link'>
      <pose frame=''>0 0 -1.015 0 -0 0</pose>
      <inertial>
        <pose frame=''>0 0 -0.29 0 -0 0</pose>
        <mass>15</mass>
        <inertia>
          <ixx>0.625</ixx>
          <ixy>0</ixy>
          <ixz>0</ixz>
          <iyy>1.562</iyy>
          <iyz>0</iyz>
          <izz>1.562</izz>
        </inertia>
      </inertial>
      <collision name='mass_link_collision'>
        <pose frame=''>0 0 0 0 -0 0</pose>
        <geometry>
          <mesh>
            <scale>1 1 1</scale>
            <uri>model://disturbance_generator/meshes/mass_link.STL</uri>
          </mesh>
        </geometry>
      </collision>
      <visual name='mass_link_visual'>
        <pose frame=''>0 0 0 0 -0 0</pose>
        <geometry>
          <mesh>
            <scale>1 1 1</scale>
            <uri>model://disturbance_generator/meshes/mass_link.STL</uri>
          </mesh>
        </geometry>
      </visual>
    </link>
    <joint name='mass_joint' type='revolute'>
      <child>mass_link</child>
      <parent>rod_link</parent>
      <axis>
        <xyz>1 0 0</xyz>
        <limit>
          <lower>-0.785</lower>
          <upper>0.785</upper>
        </limit>
        <dynamics>
          <spring_reference>0</spring_reference>
          <spring_stiffness>0</spring_stiffness>
        </dynamics>
        <use_parent_model_frame>1</use_parent_model_frame>
      </axis>
    </joint>
  </model>
</sdf>
